INFO:     Started server process [82870]
INFO:     Waiting for application startup.
INFO:     Application startup complete.
INFO:     Uvicorn running on http://127.0.0.1:8000 (Press CTRL+C to quit)
INFO:     127.0.0.1:54051 - "OPTIONS /api/recommend HTTP/1.1" 200 OK
INFO:     127.0.0.1:54051 - "POST /api/recommend HTTP/1.1" 500 Internal Server Error
ERROR:    Exception in ASGI application
Traceback (most recent call last):
  File "/Users/manunjaybhardwaj/Desktop/Ikarus/backend/app/models/recommender.py", line 21, in recommend_by_query
    from ..db.vector_db import query as query_db
  File "/Users/manunjaybhardwaj/Desktop/Ikarus/backend/app/db/vector_db.py", line 99, in <module>
    _DB = VectorDB()
          ^^^^^^^^^^
  File "/Users/manunjaybhardwaj/Desktop/Ikarus/backend/app/db/vector_db.py", line 21, in __init__
    self._init_index(INDEX_NAME)
  File "/Users/manunjaybhardwaj/Desktop/Ikarus/backend/app/db/vector_db.py", line 30, in _init_index
    import faiss
  File "/opt/anaconda3/lib/python3.12/site-packages/faiss/__init__.py", line 16, in <module>
    from .loader import *
  File "/opt/anaconda3/lib/python3.12/site-packages/faiss/loader.py", line 134, in <module>
    from .swigfaiss import *
  File "/opt/anaconda3/lib/python3.12/site-packages/faiss/swigfaiss.py", line 3321, in <module>
    class ResidualQuantizer(AdditiveQuantizer):
  File "/opt/anaconda3/lib/python3.12/site-packages/faiss/swigfaiss.py", line 3435, in ResidualQuantizer
    codebook_cross_products = property(_swigfaiss.ResidualQuantizer_codebook_cross_products_get, _swigfaiss.ResidualQuantizer_codebook_cross_products_set, doc=r"""
                                       ^^^^^^^^^^^^^^^^^^^^^^^^^^^^^^^^^^^^^^^^^^^^^^^^^^^^^^^^
AttributeError: module 'faiss._swigfaiss' has no attribute 'ResidualQuantizer_codebook_cross_products_get'

During handling of the above exception, another exception occurred:

Traceback (most recent call last):
  File "/opt/anaconda3/lib/python3.12/site-packages/uvicorn/protocols/http/httptools_impl.py", line 409, in run_asgi
    result = await app(  # type: ignore[func-returns-value]
             ^^^^^^^^^^^^^^^^^^^^^^^^^^^^^^^^^^^^^^^^^^^^^^
  File "/opt/anaconda3/lib/python3.12/site-packages/uvicorn/middleware/proxy_headers.py", line 60, in __call__
    return await self.app(scope, receive, send)
           ^^^^^^^^^^^^^^^^^^^^^^^^^^^^^^^^^^^^
  File "/opt/anaconda3/lib/python3.12/site-packages/fastapi/applications.py", line 1054, in __call__
    await super().__call__(scope, receive, send)
  File "/opt/anaconda3/lib/python3.12/site-packages/starlette/applications.py", line 112, in __call__
    await self.middleware_stack(scope, receive, send)
  File "/opt/anaconda3/lib/python3.12/site-packages/starlette/middleware/errors.py", line 187, in __call__
    raise exc
  File "/opt/anaconda3/lib/python3.12/site-packages/starlette/middleware/errors.py", line 165, in __call__
    await self.app(scope, receive, _send)
  File "/opt/anaconda3/lib/python3.12/site-packages/starlette/middleware/cors.py", line 93, in __call__
    await self.simple_response(scope, receive, send, request_headers=headers)
  File "/opt/anaconda3/lib/python3.12/site-packages/starlette/middleware/cors.py", line 144, in simple_response
    await self.app(scope, receive, send)
  File "/opt/anaconda3/lib/python3.12/site-packages/starlette/middleware/exceptions.py", line 62, in __call__
    await wrap_app_handling_exceptions(self.app, conn)(scope, receive, send)
  File "/opt/anaconda3/lib/python3.12/site-packages/starlette/_exception_handler.py", line 53, in wrapped_app
    raise exc
  File "/opt/anaconda3/lib/python3.12/site-packages/starlette/_exception_handler.py", line 42, in wrapped_app
    await app(scope, receive, sender)
  File "/opt/anaconda3/lib/python3.12/site-packages/starlette/routing.py", line 714, in __call__
    await self.middleware_stack(scope, receive, send)
  File "/opt/anaconda3/lib/python3.12/site-packages/starlette/routing.py", line 734, in app
    await route.handle(scope, receive, send)
  File "/opt/anaconda3/lib/python3.12/site-packages/starlette/routing.py", line 288, in handle
    await self.app(scope, receive, send)
  File "/opt/anaconda3/lib/python3.12/site-packages/starlette/routing.py", line 76, in app
    await wrap_app_handling_exceptions(app, request)(scope, receive, send)
  File "/opt/anaconda3/lib/python3.12/site-packages/starlette/_exception_handler.py", line 53, in wrapped_app
    raise exc
  File "/opt/anaconda3/lib/python3.12/site-packages/starlette/_exception_handler.py", line 42, in wrapped_app
    await app(scope, receive, sender)
  File "/opt/anaconda3/lib/python3.12/site-packages/starlette/routing.py", line 73, in app
    response = await f(request)
               ^^^^^^^^^^^^^^^^
  File "/opt/anaconda3/lib/python3.12/site-packages/fastapi/routing.py", line 301, in app
    raw_response = await run_endpoint_function(
                   ^^^^^^^^^^^^^^^^^^^^^^^^^^^^
  File "/opt/anaconda3/lib/python3.12/site-packages/fastapi/routing.py", line 212, in run_endpoint_function
    return await dependant.call(**values)
           ^^^^^^^^^^^^^^^^^^^^^^^^^^^^^^
  File "/Users/manunjaybhardwaj/Desktop/Ikarus/backend/app/routes/recommend.py", line 21, in recommend
    items = recommend_by_query(req.query, k=req.k)
            ^^^^^^^^^^^^^^^^^^^^^^^^^^^^^^^^^^^^^^
  File "/Users/manunjaybhardwaj/Desktop/Ikarus/backend/app/models/recommender.py", line 37, in recommend_by_query
    vals = list(meta.values())[:k]
                ^^^^^^^^^^^
AttributeError: 'list' object has no attribute 'values'
INFO:     127.0.0.1:54084 - "POST /api/recommend HTTP/1.1" 500 Internal Server Error
ERROR:    Exception in ASGI application
Traceback (most recent call last):
  File "/Users/manunjaybhardwaj/Desktop/Ikarus/backend/app/models/recommender.py", line 21, in recommend_by_query
    from ..db.vector_db import query as query_db
  File "/Users/manunjaybhardwaj/Desktop/Ikarus/backend/app/db/vector_db.py", line 99, in <module>
    _DB = VectorDB()
          ^^^^^^^^^^
  File "/Users/manunjaybhardwaj/Desktop/Ikarus/backend/app/db/vector_db.py", line 21, in __init__
    self._init_index(INDEX_NAME)
  File "/Users/manunjaybhardwaj/Desktop/Ikarus/backend/app/db/vector_db.py", line 30, in _init_index
    import faiss
  File "/opt/anaconda3/lib/python3.12/site-packages/faiss/__init__.py", line 16, in <module>
    from .loader import *
  File "/opt/anaconda3/lib/python3.12/site-packages/faiss/loader.py", line 134, in <module>
    from .swigfaiss import *
  File "/opt/anaconda3/lib/python3.12/site-packages/faiss/swigfaiss.py", line 3321, in <module>
    class ResidualQuantizer(AdditiveQuantizer):
  File "/opt/anaconda3/lib/python3.12/site-packages/faiss/swigfaiss.py", line 3435, in ResidualQuantizer
    codebook_cross_products = property(_swigfaiss.ResidualQuantizer_codebook_cross_products_get, _swigfaiss.ResidualQuantizer_codebook_cross_products_set, doc=r"""
                                       ^^^^^^^^^^^^^^^^^^^^^^^^^^^^^^^^^^^^^^^^^^^^^^^^^^^^^^^^
AttributeError: module 'faiss._swigfaiss' has no attribute 'ResidualQuantizer_codebook_cross_products_get'

During handling of the above exception, another exception occurred:

Traceback (most recent call last):
  File "/opt/anaconda3/lib/python3.12/site-packages/uvicorn/protocols/http/httptools_impl.py", line 409, in run_asgi
    result = await app(  # type: ignore[func-returns-value]
             ^^^^^^^^^^^^^^^^^^^^^^^^^^^^^^^^^^^^^^^^^^^^^^
  File "/opt/anaconda3/lib/python3.12/site-packages/uvicorn/middleware/proxy_headers.py", line 60, in __call__
    return await self.app(scope, receive, send)
           ^^^^^^^^^^^^^^^^^^^^^^^^^^^^^^^^^^^^
  File "/opt/anaconda3/lib/python3.12/site-packages/fastapi/applications.py", line 1054, in __call__
    await super().__call__(scope, receive, send)
  File "/opt/anaconda3/lib/python3.12/site-packages/starlette/applications.py", line 112, in __call__
    await self.middleware_stack(scope, receive, send)
  File "/opt/anaconda3/lib/python3.12/site-packages/starlette/middleware/errors.py", line 187, in __call__
    raise exc
  File "/opt/anaconda3/lib/python3.12/site-packages/starlette/middleware/errors.py", line 165, in __call__
    await self.app(scope, receive, _send)
  File "/opt/anaconda3/lib/python3.12/site-packages/starlette/middleware/cors.py", line 93, in __call__
    await self.simple_response(scope, receive, send, request_headers=headers)
  File "/opt/anaconda3/lib/python3.12/site-packages/starlette/middleware/cors.py", line 144, in simple_response
    await self.app(scope, receive, send)
  File "/opt/anaconda3/lib/python3.12/site-packages/starlette/middleware/exceptions.py", line 62, in __call__
    await wrap_app_handling_exceptions(self.app, conn)(scope, receive, send)
  File "/opt/anaconda3/lib/python3.12/site-packages/starlette/_exception_handler.py", line 53, in wrapped_app
    raise exc
  File "/opt/anaconda3/lib/python3.12/site-packages/starlette/_exception_handler.py", line 42, in wrapped_app
    await app(scope, receive, sender)
  File "/opt/anaconda3/lib/python3.12/site-packages/starlette/routing.py", line 714, in __call__
    await self.middleware_stack(scope, receive, send)
  File "/opt/anaconda3/lib/python3.12/site-packages/starlette/routing.py", line 734, in app
    await route.handle(scope, receive, send)
  File "/opt/anaconda3/lib/python3.12/site-packages/starlette/routing.py", line 288, in handle
    await self.app(scope, receive, send)
  File "/opt/anaconda3/lib/python3.12/site-packages/starlette/routing.py", line 76, in app
    await wrap_app_handling_exceptions(app, request)(scope, receive, send)
  File "/opt/anaconda3/lib/python3.12/site-packages/starlette/_exception_handler.py", line 53, in wrapped_app
    raise exc
  File "/opt/anaconda3/lib/python3.12/site-packages/starlette/_exception_handler.py", line 42, in wrapped_app
    await app(scope, receive, sender)
  File "/opt/anaconda3/lib/python3.12/site-packages/starlette/routing.py", line 73, in app
    response = await f(request)
               ^^^^^^^^^^^^^^^^
  File "/opt/anaconda3/lib/python3.12/site-packages/fastapi/routing.py", line 301, in app
    raw_response = await run_endpoint_function(
                   ^^^^^^^^^^^^^^^^^^^^^^^^^^^^
  File "/opt/anaconda3/lib/python3.12/site-packages/fastapi/routing.py", line 212, in run_endpoint_function
    return await dependant.call(**values)
           ^^^^^^^^^^^^^^^^^^^^^^^^^^^^^^
  File "/Users/manunjaybhardwaj/Desktop/Ikarus/backend/app/routes/recommend.py", line 21, in recommend
    items = recommend_by_query(req.query, k=req.k)
            ^^^^^^^^^^^^^^^^^^^^^^^^^^^^^^^^^^^^^^
  File "/Users/manunjaybhardwaj/Desktop/Ikarus/backend/app/models/recommender.py", line 37, in recommend_by_query
    vals = list(meta.values())[:k]
                ^^^^^^^^^^^
AttributeError: 'list' object has no attribute 'values'
INFO:     127.0.0.1:54100 - "POST /api/recommend HTTP/1.1" 500 Internal Server Error
ERROR:    Exception in ASGI application
Traceback (most recent call last):
  File "/Users/manunjaybhardwaj/Desktop/Ikarus/backend/app/models/recommender.py", line 21, in recommend_by_query
    from ..db.vector_db import query as query_db
  File "/Users/manunjaybhardwaj/Desktop/Ikarus/backend/app/db/vector_db.py", line 99, in <module>
    _DB = VectorDB()
          ^^^^^^^^^^
  File "/Users/manunjaybhardwaj/Desktop/Ikarus/backend/app/db/vector_db.py", line 21, in __init__
    self._init_index(INDEX_NAME)
  File "/Users/manunjaybhardwaj/Desktop/Ikarus/backend/app/db/vector_db.py", line 30, in _init_index
    import faiss
  File "/opt/anaconda3/lib/python3.12/site-packages/faiss/__init__.py", line 16, in <module>
    from .loader import *
  File "/opt/anaconda3/lib/python3.12/site-packages/faiss/loader.py", line 134, in <module>
    from .swigfaiss import *
  File "/opt/anaconda3/lib/python3.12/site-packages/faiss/swigfaiss.py", line 3321, in <module>
    class ResidualQuantizer(AdditiveQuantizer):
  File "/opt/anaconda3/lib/python3.12/site-packages/faiss/swigfaiss.py", line 3435, in ResidualQuantizer
    codebook_cross_products = property(_swigfaiss.ResidualQuantizer_codebook_cross_products_get, _swigfaiss.ResidualQuantizer_codebook_cross_products_set, doc=r"""
                                       ^^^^^^^^^^^^^^^^^^^^^^^^^^^^^^^^^^^^^^^^^^^^^^^^^^^^^^^^
AttributeError: module 'faiss._swigfaiss' has no attribute 'ResidualQuantizer_codebook_cross_products_get'

During handling of the above exception, another exception occurred:

Traceback (most recent call last):
  File "/opt/anaconda3/lib/python3.12/site-packages/uvicorn/protocols/http/httptools_impl.py", line 409, in run_asgi
    result = await app(  # type: ignore[func-returns-value]
             ^^^^^^^^^^^^^^^^^^^^^^^^^^^^^^^^^^^^^^^^^^^^^^
  File "/opt/anaconda3/lib/python3.12/site-packages/uvicorn/middleware/proxy_headers.py", line 60, in __call__
    return await self.app(scope, receive, send)
           ^^^^^^^^^^^^^^^^^^^^^^^^^^^^^^^^^^^^
  File "/opt/anaconda3/lib/python3.12/site-packages/fastapi/applications.py", line 1054, in __call__
    await super().__call__(scope, receive, send)
  File "/opt/anaconda3/lib/python3.12/site-packages/starlette/applications.py", line 112, in __call__
    await self.middleware_stack(scope, receive, send)
  File "/opt/anaconda3/lib/python3.12/site-packages/starlette/middleware/errors.py", line 187, in __call__
    raise exc
  File "/opt/anaconda3/lib/python3.12/site-packages/starlette/middleware/errors.py", line 165, in __call__
    await self.app(scope, receive, _send)
  File "/opt/anaconda3/lib/python3.12/site-packages/starlette/middleware/cors.py", line 93, in __call__
    await self.simple_response(scope, receive, send, request_headers=headers)
  File "/opt/anaconda3/lib/python3.12/site-packages/starlette/middleware/cors.py", line 144, in simple_response
    await self.app(scope, receive, send)
  File "/opt/anaconda3/lib/python3.12/site-packages/starlette/middleware/exceptions.py", line 62, in __call__
    await wrap_app_handling_exceptions(self.app, conn)(scope, receive, send)
  File "/opt/anaconda3/lib/python3.12/site-packages/starlette/_exception_handler.py", line 53, in wrapped_app
    raise exc
  File "/opt/anaconda3/lib/python3.12/site-packages/starlette/_exception_handler.py", line 42, in wrapped_app
    await app(scope, receive, sender)
  File "/opt/anaconda3/lib/python3.12/site-packages/starlette/routing.py", line 714, in __call__
    await self.middleware_stack(scope, receive, send)
  File "/opt/anaconda3/lib/python3.12/site-packages/starlette/routing.py", line 734, in app
    await route.handle(scope, receive, send)
  File "/opt/anaconda3/lib/python3.12/site-packages/starlette/routing.py", line 288, in handle
    await self.app(scope, receive, send)
  File "/opt/anaconda3/lib/python3.12/site-packages/starlette/routing.py", line 76, in app
    await wrap_app_handling_exceptions(app, request)(scope, receive, send)
  File "/opt/anaconda3/lib/python3.12/site-packages/starlette/_exception_handler.py", line 53, in wrapped_app
    raise exc
  File "/opt/anaconda3/lib/python3.12/site-packages/starlette/_exception_handler.py", line 42, in wrapped_app
    await app(scope, receive, sender)
  File "/opt/anaconda3/lib/python3.12/site-packages/starlette/routing.py", line 73, in app
    response = await f(request)
               ^^^^^^^^^^^^^^^^
  File "/opt/anaconda3/lib/python3.12/site-packages/fastapi/routing.py", line 301, in app
    raw_response = await run_endpoint_function(
                   ^^^^^^^^^^^^^^^^^^^^^^^^^^^^
  File "/opt/anaconda3/lib/python3.12/site-packages/fastapi/routing.py", line 212, in run_endpoint_function
    return await dependant.call(**values)
           ^^^^^^^^^^^^^^^^^^^^^^^^^^^^^^
  File "/Users/manunjaybhardwaj/Desktop/Ikarus/backend/app/routes/recommend.py", line 21, in recommend
    items = recommend_by_query(req.query, k=req.k)
            ^^^^^^^^^^^^^^^^^^^^^^^^^^^^^^^^^^^^^^
  File "/Users/manunjaybhardwaj/Desktop/Ikarus/backend/app/models/recommender.py", line 37, in recommend_by_query
    vals = list(meta.values())[:k]
                ^^^^^^^^^^^
AttributeError: 'list' object has no attribute 'values'
INFO:     127.0.0.1:54595 - "GET /api/sample-data?n=3 HTTP/1.1" 200 OK
INFO:     127.0.0.1:54727 - "POST /api/recommend HTTP/1.1" 500 Internal Server Error
ERROR:    Exception in ASGI application
Traceback (most recent call last):
  File "/Users/manunjaybhardwaj/Desktop/Ikarus/backend/app/models/recommender.py", line 21, in recommend_by_query
    from ..db.vector_db import query as query_db
  File "/Users/manunjaybhardwaj/Desktop/Ikarus/backend/app/db/vector_db.py", line 99, in <module>
    _DB = VectorDB()
          ^^^^^^^^^^
  File "/Users/manunjaybhardwaj/Desktop/Ikarus/backend/app/db/vector_db.py", line 21, in __init__
    self._init_index(INDEX_NAME)
  File "/Users/manunjaybhardwaj/Desktop/Ikarus/backend/app/db/vector_db.py", line 30, in _init_index
    import faiss
  File "/opt/anaconda3/lib/python3.12/site-packages/faiss/__init__.py", line 16, in <module>
    from .loader import *
  File "/opt/anaconda3/lib/python3.12/site-packages/faiss/loader.py", line 134, in <module>
    from .swigfaiss import *
  File "/opt/anaconda3/lib/python3.12/site-packages/faiss/swigfaiss.py", line 3321, in <module>
    class ResidualQuantizer(AdditiveQuantizer):
  File "/opt/anaconda3/lib/python3.12/site-packages/faiss/swigfaiss.py", line 3435, in ResidualQuantizer
    codebook_cross_products = property(_swigfaiss.ResidualQuantizer_codebook_cross_products_get, _swigfaiss.ResidualQuantizer_codebook_cross_products_set, doc=r"""
                                       ^^^^^^^^^^^^^^^^^^^^^^^^^^^^^^^^^^^^^^^^^^^^^^^^^^^^^^^^
AttributeError: module 'faiss._swigfaiss' has no attribute 'ResidualQuantizer_codebook_cross_products_get'

During handling of the above exception, another exception occurred:

Traceback (most recent call last):
  File "/opt/anaconda3/lib/python3.12/site-packages/uvicorn/protocols/http/httptools_impl.py", line 409, in run_asgi
    result = await app(  # type: ignore[func-returns-value]
             ^^^^^^^^^^^^^^^^^^^^^^^^^^^^^^^^^^^^^^^^^^^^^^
  File "/opt/anaconda3/lib/python3.12/site-packages/uvicorn/middleware/proxy_headers.py", line 60, in __call__
    return await self.app(scope, receive, send)
           ^^^^^^^^^^^^^^^^^^^^^^^^^^^^^^^^^^^^
  File "/opt/anaconda3/lib/python3.12/site-packages/fastapi/applications.py", line 1054, in __call__
    await super().__call__(scope, receive, send)
  File "/opt/anaconda3/lib/python3.12/site-packages/starlette/applications.py", line 112, in __call__
    await self.middleware_stack(scope, receive, send)
  File "/opt/anaconda3/lib/python3.12/site-packages/starlette/middleware/errors.py", line 187, in __call__
    raise exc
  File "/opt/anaconda3/lib/python3.12/site-packages/starlette/middleware/errors.py", line 165, in __call__
    await self.app(scope, receive, _send)
  File "/opt/anaconda3/lib/python3.12/site-packages/starlette/middleware/cors.py", line 85, in __call__
    await self.app(scope, receive, send)
  File "/opt/anaconda3/lib/python3.12/site-packages/starlette/middleware/exceptions.py", line 62, in __call__
    await wrap_app_handling_exceptions(self.app, conn)(scope, receive, send)
  File "/opt/anaconda3/lib/python3.12/site-packages/starlette/_exception_handler.py", line 53, in wrapped_app
    raise exc
  File "/opt/anaconda3/lib/python3.12/site-packages/starlette/_exception_handler.py", line 42, in wrapped_app
    await app(scope, receive, sender)
  File "/opt/anaconda3/lib/python3.12/site-packages/starlette/routing.py", line 714, in __call__
    await self.middleware_stack(scope, receive, send)
  File "/opt/anaconda3/lib/python3.12/site-packages/starlette/routing.py", line 734, in app
    await route.handle(scope, receive, send)
  File "/opt/anaconda3/lib/python3.12/site-packages/starlette/routing.py", line 288, in handle
    await self.app(scope, receive, send)
  File "/opt/anaconda3/lib/python3.12/site-packages/starlette/routing.py", line 76, in app
    await wrap_app_handling_exceptions(app, request)(scope, receive, send)
  File "/opt/anaconda3/lib/python3.12/site-packages/starlette/_exception_handler.py", line 53, in wrapped_app
    raise exc
  File "/opt/anaconda3/lib/python3.12/site-packages/starlette/_exception_handler.py", line 42, in wrapped_app
    await app(scope, receive, sender)
  File "/opt/anaconda3/lib/python3.12/site-packages/starlette/routing.py", line 73, in app
    response = await f(request)
               ^^^^^^^^^^^^^^^^
  File "/opt/anaconda3/lib/python3.12/site-packages/fastapi/routing.py", line 301, in app
    raw_response = await run_endpoint_function(
                   ^^^^^^^^^^^^^^^^^^^^^^^^^^^^
  File "/opt/anaconda3/lib/python3.12/site-packages/fastapi/routing.py", line 212, in run_endpoint_function
    return await dependant.call(**values)
           ^^^^^^^^^^^^^^^^^^^^^^^^^^^^^^
  File "/Users/manunjaybhardwaj/Desktop/Ikarus/backend/app/routes/recommend.py", line 21, in recommend
    items = recommend_by_query(req.query, k=req.k)
            ^^^^^^^^^^^^^^^^^^^^^^^^^^^^^^^^^^^^^^
  File "/Users/manunjaybhardwaj/Desktop/Ikarus/backend/app/models/recommender.py", line 37, in recommend_by_query
    vals = list(meta.values())[:k]
                ^^^^^^^^^^^
AttributeError: 'list' object has no attribute 'values'
INFO:     127.0.0.1:54894 - "POST /api/recommend HTTP/1.1" 500 Internal Server Error
ERROR:    Exception in ASGI application
Traceback (most recent call last):
  File "/Users/manunjaybhardwaj/Desktop/Ikarus/backend/app/models/recommender.py", line 21, in recommend_by_query
    from ..db.vector_db import query as query_db
  File "/Users/manunjaybhardwaj/Desktop/Ikarus/backend/app/db/vector_db.py", line 99, in <module>
    _DB = VectorDB()
          ^^^^^^^^^^
  File "/Users/manunjaybhardwaj/Desktop/Ikarus/backend/app/db/vector_db.py", line 21, in __init__
    self._init_index(INDEX_NAME)
  File "/Users/manunjaybhardwaj/Desktop/Ikarus/backend/app/db/vector_db.py", line 30, in _init_index
    import faiss
  File "/opt/anaconda3/lib/python3.12/site-packages/faiss/__init__.py", line 16, in <module>
    from .loader import *
  File "/opt/anaconda3/lib/python3.12/site-packages/faiss/loader.py", line 134, in <module>
    from .swigfaiss import *
  File "/opt/anaconda3/lib/python3.12/site-packages/faiss/swigfaiss.py", line 3321, in <module>
    class ResidualQuantizer(AdditiveQuantizer):
  File "/opt/anaconda3/lib/python3.12/site-packages/faiss/swigfaiss.py", line 3435, in ResidualQuantizer
    codebook_cross_products = property(_swigfaiss.ResidualQuantizer_codebook_cross_products_get, _swigfaiss.ResidualQuantizer_codebook_cross_products_set, doc=r"""
                                       ^^^^^^^^^^^^^^^^^^^^^^^^^^^^^^^^^^^^^^^^^^^^^^^^^^^^^^^^
AttributeError: module 'faiss._swigfaiss' has no attribute 'ResidualQuantizer_codebook_cross_products_get'

During handling of the above exception, another exception occurred:

Traceback (most recent call last):
  File "/opt/anaconda3/lib/python3.12/site-packages/uvicorn/protocols/http/httptools_impl.py", line 409, in run_asgi
    result = await app(  # type: ignore[func-returns-value]
             ^^^^^^^^^^^^^^^^^^^^^^^^^^^^^^^^^^^^^^^^^^^^^^
  File "/opt/anaconda3/lib/python3.12/site-packages/uvicorn/middleware/proxy_headers.py", line 60, in __call__
    return await self.app(scope, receive, send)
           ^^^^^^^^^^^^^^^^^^^^^^^^^^^^^^^^^^^^
  File "/opt/anaconda3/lib/python3.12/site-packages/fastapi/applications.py", line 1054, in __call__
    await super().__call__(scope, receive, send)
  File "/opt/anaconda3/lib/python3.12/site-packages/starlette/applications.py", line 112, in __call__
    await self.middleware_stack(scope, receive, send)
  File "/opt/anaconda3/lib/python3.12/site-packages/starlette/middleware/errors.py", line 187, in __call__
    raise exc
  File "/opt/anaconda3/lib/python3.12/site-packages/starlette/middleware/errors.py", line 165, in __call__
    await self.app(scope, receive, _send)
  File "/opt/anaconda3/lib/python3.12/site-packages/starlette/middleware/cors.py", line 85, in __call__
    await self.app(scope, receive, send)
  File "/opt/anaconda3/lib/python3.12/site-packages/starlette/middleware/exceptions.py", line 62, in __call__
    await wrap_app_handling_exceptions(self.app, conn)(scope, receive, send)
  File "/opt/anaconda3/lib/python3.12/site-packages/starlette/_exception_handler.py", line 53, in wrapped_app
    raise exc
  File "/opt/anaconda3/lib/python3.12/site-packages/starlette/_exception_handler.py", line 42, in wrapped_app
    await app(scope, receive, sender)
  File "/opt/anaconda3/lib/python3.12/site-packages/starlette/routing.py", line 714, in __call__
    await self.middleware_stack(scope, receive, send)
  File "/opt/anaconda3/lib/python3.12/site-packages/starlette/routing.py", line 734, in app
    await route.handle(scope, receive, send)
  File "/opt/anaconda3/lib/python3.12/site-packages/starlette/routing.py", line 288, in handle
    await self.app(scope, receive, send)
  File "/opt/anaconda3/lib/python3.12/site-packages/starlette/routing.py", line 76, in app
    await wrap_app_handling_exceptions(app, request)(scope, receive, send)
  File "/opt/anaconda3/lib/python3.12/site-packages/starlette/_exception_handler.py", line 53, in wrapped_app
    raise exc
  File "/opt/anaconda3/lib/python3.12/site-packages/starlette/_exception_handler.py", line 42, in wrapped_app
    await app(scope, receive, sender)
  File "/opt/anaconda3/lib/python3.12/site-packages/starlette/routing.py", line 73, in app
    response = await f(request)
               ^^^^^^^^^^^^^^^^
  File "/opt/anaconda3/lib/python3.12/site-packages/fastapi/routing.py", line 301, in app
    raw_response = await run_endpoint_function(
                   ^^^^^^^^^^^^^^^^^^^^^^^^^^^^
  File "/opt/anaconda3/lib/python3.12/site-packages/fastapi/routing.py", line 212, in run_endpoint_function
    return await dependant.call(**values)
           ^^^^^^^^^^^^^^^^^^^^^^^^^^^^^^
  File "/Users/manunjaybhardwaj/Desktop/Ikarus/backend/app/routes/recommend.py", line 21, in recommend
    items = recommend_by_query(req.query, k=req.k)
            ^^^^^^^^^^^^^^^^^^^^^^^^^^^^^^^^^^^^^^
  File "/Users/manunjaybhardwaj/Desktop/Ikarus/backend/app/models/recommender.py", line 37, in recommend_by_query
    vals = list(meta.values())[:k]
                ^^^^^^^^^^^
AttributeError: 'list' object has no attribute 'values'
INFO:     Shutting down
INFO:     Waiting for application shutdown.
INFO:     Application shutdown complete.
INFO:     Finished server process [82870]
